<?xml version="1.0" ?>
<robot xmlns:xacro="http://ros.org/wiki/xacro">
  <xacro:include filename="$(find vega)/urdf/common_properties.xacro"/>

  

  <joint name="base_joint" type="fixed">
    <parent link="base_footprint"/>
    <child link="base_link" />
    <origin xyz="0 0 0.010" rpy="0 0 0"/>
  </joint>

  <link name="base_link">
    <visual>
      <origin xyz="-0.064 0 0.0" rpy="1.57075 0 0"/>
      <geometry>
        <mesh filename="package://vega/meshes/VEGA_Assembly.stl" scale="0.001 0.001 0.001"/>
      </geometry>
      <material name="light_black"/>
    </visual>
    <collision>
      <origin xyz="-0.064 0 0.047" rpy="0 0 0"/>
      <geometry>
        <box size="0.266 0.266 0.094"/>
      </geometry>
    </collision>
  </link>

  <joint name="wheel_left_joint" type="continuous">
    <parent link="base_link"/>
    <child link="wheel_left_link"/>
    <origin xyz="-0.0675 0.140 0.035" rpy="-1.57 0 0"/>
    <axis xyz="0 0 1"/>
  </joint>

  <link name="wheel_left_link">
      <origin xyz="0 0 0" rpy="1.57 0 1.57"/>
      <material name="dark"/>
    <collision>
      <origin xyz="0 0 0" rpy="0 0 0"/>
      <geometry>
        <cylinder length="0.018" radius="0.033"/>
      </geometry>
    </collision>
  </link>

  <joint name="wheel_left_body" type="fixed">
    <parent link="base_link"/>
    <child link="wheel_left_body"/>
    <origin xyz="-0.0675 0.140 0.035" rpy="-1.57 0 0"/>
    <axis xyz="0 0 1"/>
  </joint>

<link name="wheel_left_body">
    <visual>
      <origin xyz="0 0 0" rpy="1.57 0 1.57"/>
      <geometry>
        <mesh filename="package://vega/meshes/track_assembly.stl" scale="0.001 0.001 0.001"/>
      </geometry>
      <material name="dark"/>
    </visual>
</link>

  <joint name="wheel_right_joint" type="continuous">
    <parent link="base_link"/>
    <child link="wheel_right_link"/>
    <origin xyz="-0.0675 -0.140 0.035" rpy="-1.57 0 0"/>
    <axis xyz="0 0 1"/>
  </joint>

    <link name="wheel_right_link">
      <origin xyz="0 0 0" rpy="1.57 3.14 1.57"/>
      <material name="dark"/>
    <collision>
      <origin xyz="0 0 0" rpy="0 0 0"/>
      <geometry>
        <cylinder length="0.018" radius="0.033"/>
      </geometry>
    </collision>
  </link>

   <joint name="wheel_right_body" type="fixed">
    <parent link="base_link"/>
    <child link="wheel_right_body"/>
    <origin xyz="-0.0675 -0.140 0.035" rpy="-1.57 0 0"/>
    <axis xyz="0 0 1"/>
  </joint>

<link name="wheel_right_body">
    <visual>
      <origin xyz="0 0 0" rpy="1.57 3.14 1.57"/>
      <geometry>
        <mesh filename="package://vega/meshes/track_assembly.stl" scale="0.001 0.001 0.001"/>
      </geometry>
      <material name="dark"/>
    </visual>
   </link>

  <joint name="imu_joint" type="fixed">
    <parent link="base_link"/>
    <child link="imu_link"/>
    <origin xyz="0.0 0 0.068" rpy="0 0 0"/>
  </joint>

  <link name="imu_link"/>

  <joint name="scan_joint" type="fixed">
    <parent link="base_link"/>
    <child link="base_scan"/>
    <origin xyz="0.013 -0.057 0.068" rpy="0 0 3.14"/> 
  </joint>

  <link name="base_scan">
    <visual>
      <origin xyz="0 0 0.0" rpy="1.57 0 3.14"/>
      <geometry>
        <mesh filename="package://vega/meshes/RP_lidar_A1.stl" scale="0.001 0.001 0.001"/>
      </geometry>
      <material name="dark"/>
    </visual>

    <collision>
      <origin xyz="0.015 0 -0.0065" rpy="0 0 0"/>
      <geometry>
        <cylinder length="0.0315" radius="0.045"/>
      </geometry>
    </collision>

  </link>

  <joint name="camera_joint" type="fixed">
    <origin xyz="0.073 -0.015 0.0825" rpy="0 0 0"/>
    <parent link="base_link"/>
    <child link="camera_link"/>
  </joint>

  <link name="camera_link">
  	<visual>
      <origin xyz="0.0 0.0 0.0" rpy="-1.57 3.14 1.57"/>
      <geometry>
        <mesh filename="package://vega/meshes/Intel_RealSense_Depth_Camera_D435.stl" scale="0.001 0.001 0.001"/>
      </geometry>
      <material name ="dark"/>
    </visual>

	<collision>
      <origin xyz="0.015 0 -0.0065" rpy="0 0 0"/>
      <geometry>
        <cylinder length="0.0315" radius="0.045"/>
      </geometry>
    </collision>


  </link>

  <joint name="camera_rgb_joint" type="fixed">
    <origin xyz="0.003 0.011 0.009" rpy="0 0 0"/>
    <parent link="camera_link"/>
    <child link="camera_rgb_frame"/>
  </joint>
  <link name="camera_rgb_frame"/>

  <joint name="camera_rgb_optical_joint" type="fixed">
    <origin xyz="0 0 0" rpy="-1.57 0 -1.57"/>
    <parent link="camera_rgb_frame"/>
    <child link="camera_rgb_optical_frame"/>
  </joint>
  <link name="camera_rgb_optical_frame"/>

</robot>
