<robot name="test_robot">

  <link name="base">
  <inertial>
    <mass value="0.2"/>
    <inertia ixx="100" ixy="0" ixz="0" iyy="100" iyz="0" izz="100" />
    <origin/>
  </inertial>
  <visual>
    <origin xyz="0.00 0.00 0.015" rpy="0 0 0" />
    <geometry>
      <box size="0.09 0.09 0.03" />
    </geometry>
    <material name="gray">
      <color rgba=".2 .2 .2 1" />
    </material>
  </visual>
  </link>


  <link name="spinner">
  <inertial>
    <mass value="0.2"/>
    <inertia ixx="100" ixy="0" ixz="0" iyy="100" iyz="0" izz="100" />
    <origin/>
  </inertial>
  <visual>
    <origin xyz="-0.011 0.0 0.034" rpy="0 0 0" />
    <geometry>
      <box size="0.11 0.06 0.068" />
    </geometry>
    <material name="blue">
      <color rgba=".1 .1 .8 1" />
    </material>
  </visual>
  </link>


  <link name="recon_lidar">
  <inertial>
    <mass value="0.2"/>
    <inertia ixx="100" ixy="0" ixz="0" iyy="100" iyz="0" izz="100" />
    <origin/>
  </inertial>
  <visual>
    <origin xyz="0.00 0.0 0.0" rpy="0 0 0" />
    <geometry>
      <box size="0.06 0.05 0.05" />
    </geometry>
    <material name="lightGray">
      <color rgba=".6 .6 .8 6" />
    </material>
  </visual>
  </link>

  <joint name="recon_joint" type="continuous">
    <parent link="base"/>
    <child link="spinner"/>
    <origin xyz="0 0 0.035" rpy="0 0 0" />
    <axis xyz="0.0 0.0 -1.0" />
  </joint>

  <joint name="spinner_lidar" type="fixed">
    <parent link="spinner"/>
    <child link="recon_lidar"/>
    <origin xyz="0 0 0.101" rpy="0 -1.57 3.14" />
    <axis xyz="0.0 0.0 1.0" />
  </joint>

</robot>
