<?xml version="1.0" ?>
<robot xmlns:xacro="http://ros.org/wiki/xacro">

<!-- <robot name="test_robot"> -->

  <link name="link1">
  <inertial>
    <mass value="0.2"/>
    <inertia ixx="100" ixy="0" ixz="0" iyy="100" iyz="0" izz="100" />
    <origin/>
  </inertial>
  </link>


  <link name="spinner">
  <inertial>
    <mass value="0.2"/>
    <inertia ixx="100" ixy="0" ixz="0" iyy="100" iyz="0" izz="100" />
    <origin/>
  </inertial>
  </link>


  <link name="recon_lidar">
  <inertial>
    <mass value="0.2"/>
    <inertia ixx="100" ixy="0" ixz="0" iyy="100" iyz="0" izz="100" />
    <origin/>
  </inertial>
  </link>

  <joint name="recon_joint" type="continuous">
    <parent link="link1"/>
    <child link="spinner"/>
    <origin xyz="0 0 0.035" rpy="0 0 0" />
    <axis xyz="0.0 0.0 1.0" />
  </joint>

  <joint name="spinner_lidar" type="fixed">
    <parent link="spinner"/>
    <child link="recon_lidar"/>
    <origin xyz="-0.02 0 0.041" rpy="0 -1.57 -1.57" />
    <axis xyz="0.0 0.0 1.0" />
  </joint>

</robot>
